[2023-09-29T14:04:43.888+0000] {taskinstance.py:1157} INFO - Dependencies all met for dep_context=non-requeueable deps ti=<TaskInstance: btc_market_analysis.load_data_from_mongo manual__2023-09-29T13:54:30.163720+00:00 [queued]>
[2023-09-29T14:04:43.893+0000] {taskinstance.py:1157} INFO - Dependencies all met for dep_context=requeueable deps ti=<TaskInstance: btc_market_analysis.load_data_from_mongo manual__2023-09-29T13:54:30.163720+00:00 [queued]>
[2023-09-29T14:04:43.893+0000] {taskinstance.py:1359} INFO - Starting attempt 2 of 2
[2023-09-29T14:04:43.900+0000] {taskinstance.py:1380} INFO - Executing <Task(PythonOperator): load_data_from_mongo> on 2023-09-29 13:54:30.163720+00:00
[2023-09-29T14:04:43.908+0000] {standard_task_runner.py:57} INFO - Started process 364 to run task
[2023-09-29T14:04:43.913+0000] {standard_task_runner.py:84} INFO - Running: ['***', 'tasks', 'run', 'btc_market_analysis', 'load_data_from_mongo', 'manual__2023-09-29T13:54:30.163720+00:00', '--job-id', '10', '--raw', '--subdir', 'DAGS_FOLDER/crypto_dag.py', '--cfg-path', '/tmp/tmp5pnrekga']
[2023-09-29T14:04:43.915+0000] {standard_task_runner.py:85} INFO - Job 10: Subtask load_data_from_mongo
[2023-09-29T14:04:43.958+0000] {task_command.py:415} INFO - Running <TaskInstance: btc_market_analysis.load_data_from_mongo manual__2023-09-29T13:54:30.163720+00:00 [running]> on host 93a54927beb5
[2023-09-29T14:04:44.026+0000] {taskinstance.py:1660} INFO - Exporting env vars: AIRFLOW_CTX_DAG_OWNER='***' AIRFLOW_CTX_DAG_ID='btc_market_analysis' AIRFLOW_CTX_TASK_ID='load_data_from_mongo' AIRFLOW_CTX_EXECUTION_DATE='2023-09-29T13:54:30.163720+00:00' AIRFLOW_CTX_TRY_NUMBER='2' AIRFLOW_CTX_DAG_RUN_ID='manual__2023-09-29T13:54:30.163720+00:00'
[2023-09-29T14:04:59.556+0000] {clientserver.py:538} INFO - Error while receiving.
Traceback (most recent call last):
  File "/home/airflow/.local/lib/python3.8/site-packages/py4j/clientserver.py", line 516, in send_command
    raise Py4JNetworkError("Answer from Java side is empty")
py4j.protocol.Py4JNetworkError: Answer from Java side is empty
[2023-09-29T14:04:59.689+0000] {clientserver.py:543} INFO - Closing down clientserver connection
[2023-09-29T14:04:59.700+0000] {java_gateway.py:1055} ERROR - Exception while sending command.
Traceback (most recent call last):
  File "/home/airflow/.local/lib/python3.8/site-packages/py4j/clientserver.py", line 516, in send_command
    raise Py4JNetworkError("Answer from Java side is empty")
py4j.protocol.Py4JNetworkError: Answer from Java side is empty

During handling of the above exception, another exception occurred:

Traceback (most recent call last):
  File "/home/airflow/.local/lib/python3.8/site-packages/py4j/java_gateway.py", line 1038, in send_command
    response = connection.send_command(command)
  File "/home/airflow/.local/lib/python3.8/site-packages/py4j/clientserver.py", line 539, in send_command
    raise Py4JNetworkError(
py4j.protocol.Py4JNetworkError: Error while sending or receiving
[2023-09-29T14:04:59.728+0000] {clientserver.py:543} INFO - Closing down clientserver connection
[2023-09-29T14:04:59.735+0000] {taskinstance.py:1935} ERROR - Task failed with exception
Traceback (most recent call last):
  File "/home/airflow/.local/lib/python3.8/site-packages/airflow/operators/python.py", line 192, in execute
    return_value = self.execute_callable()
  File "/home/airflow/.local/lib/python3.8/site-packages/airflow/operators/python.py", line 209, in execute_callable
    return self.python_callable(*self.op_args, **self.op_kwargs)
  File "/opt/airflow/dags/crypto_dag.py", line 87, in load_data_from_mongo
    df = spark.read.format('mongo') \
  File "/home/airflow/.local/lib/python3.8/site-packages/pyspark/sql/readwriter.py", line 307, in load
    return self._df(self._jreader.load())
  File "/home/airflow/.local/lib/python3.8/site-packages/py4j/java_gateway.py", line 1322, in __call__
    return_value = get_return_value(
  File "/home/airflow/.local/lib/python3.8/site-packages/pyspark/errors/exceptions/captured.py", line 169, in deco
    return f(*a, **kw)
  File "/home/airflow/.local/lib/python3.8/site-packages/py4j/protocol.py", line 334, in get_return_value
    raise Py4JError(
py4j.protocol.Py4JError: An error occurred while calling o38.load
[2023-09-29T14:04:59.912+0000] {taskinstance.py:1398} INFO - Marking task as FAILED. dag_id=btc_market_analysis, task_id=load_data_from_mongo, execution_date=20230929T135430, start_date=20230929T140443, end_date=20230929T140459
[2023-09-29T14:04:59.969+0000] {standard_task_runner.py:104} ERROR - Failed to execute job 10 for task load_data_from_mongo (An error occurred while calling o38.load; 364)
[2023-09-29T14:05:00.033+0000] {local_task_job_runner.py:228} INFO - Task exited with return code 1
[2023-09-29T14:05:00.106+0000] {taskinstance.py:2776} INFO - 0 downstream tasks scheduled from follow-on schedule check
