[2023-09-30T10:22:55.674+0000] {taskinstance.py:1157} INFO - Dependencies all met for dep_context=non-requeueable deps ti=<TaskInstance: btc_market_analysis.load_data_from_mongo manual__2023-09-30T09:48:05.564572+00:00 [queued]>
[2023-09-30T10:22:55.683+0000] {taskinstance.py:1157} INFO - Dependencies all met for dep_context=requeueable deps ti=<TaskInstance: btc_market_analysis.load_data_from_mongo manual__2023-09-30T09:48:05.564572+00:00 [queued]>
[2023-09-30T10:22:55.683+0000] {taskinstance.py:1359} INFO - Starting attempt 4 of 5
[2023-09-30T10:22:55.691+0000] {taskinstance.py:1380} INFO - Executing <Task(PythonOperator): load_data_from_mongo> on 2023-09-30 09:48:05.564572+00:00
[2023-09-30T10:22:55.707+0000] {standard_task_runner.py:57} INFO - Started process 211 to run task
[2023-09-30T10:22:55.712+0000] {standard_task_runner.py:84} INFO - Running: ['airflow', 'tasks', 'run', 'btc_market_analysis', 'load_data_from_mongo', 'manual__2023-09-30T09:48:05.564572+00:00', '--job-id', '29', '--raw', '--subdir', 'DAGS_FOLDER/dag.py', '--cfg-path', '/tmp/tmpd63fvsti']
[2023-09-30T10:22:55.714+0000] {standard_task_runner.py:85} INFO - Job 29: Subtask load_data_from_mongo
[2023-09-30T10:22:55.772+0000] {task_command.py:415} INFO - Running <TaskInstance: btc_market_analysis.load_data_from_mongo manual__2023-09-30T09:48:05.564572+00:00 [running]> on host bdec796fb08e
[2023-09-30T10:22:55.855+0000] {taskinstance.py:1660} INFO - Exporting env vars: AIRFLOW_CTX_DAG_OWNER='airflow' AIRFLOW_CTX_DAG_ID='btc_market_analysis' AIRFLOW_CTX_TASK_ID='load_data_from_mongo' AIRFLOW_CTX_EXECUTION_DATE='2023-09-30T09:48:05.564572+00:00' AIRFLOW_CTX_TRY_NUMBER='4' AIRFLOW_CTX_DAG_RUN_ID='manual__2023-09-30T09:48:05.564572+00:00'
[2023-09-30T10:23:01.420+0000] {taskinstance.py:1935} ERROR - Task failed with exception
Traceback (most recent call last):
  File "/home/airflow/.local/lib/python3.8/site-packages/airflow/operators/python.py", line 192, in execute
    return_value = self.execute_callable()
  File "/home/airflow/.local/lib/python3.8/site-packages/airflow/operators/python.py", line 209, in execute_callable
    return self.python_callable(*self.op_args, **self.op_kwargs)
  File "/opt/airflow/dags/dag.py", line 71, in load_data_from_mongo
    df = spark.read.format('mongo') \
  File "/home/airflow/.local/lib/python3.8/site-packages/pyspark/sql/readwriter.py", line 314, in load
    return self._df(self._jreader.load())
  File "/home/airflow/.local/lib/python3.8/site-packages/py4j/java_gateway.py", line 1322, in __call__
    return_value = get_return_value(
  File "/home/airflow/.local/lib/python3.8/site-packages/pyspark/errors/exceptions/captured.py", line 179, in deco
    return f(*a, **kw)
  File "/home/airflow/.local/lib/python3.8/site-packages/py4j/protocol.py", line 326, in get_return_value
    raise Py4JJavaError(
py4j.protocol.Py4JJavaError: An error occurred while calling o29.load.
: org.apache.spark.SparkClassNotFoundException: [DATA_SOURCE_NOT_FOUND] Failed to find the data source: mongo. Please find packages at `https://spark.apache.org/third-party-projects.html`.
	at org.apache.spark.sql.errors.QueryExecutionErrors$.dataSourceNotFoundError(QueryExecutionErrors.scala:724)
	at org.apache.spark.sql.execution.datasources.DataSource$.lookupDataSource(DataSource.scala:647)
	at org.apache.spark.sql.execution.datasources.DataSource$.lookupDataSourceV2(DataSource.scala:697)
	at org.apache.spark.sql.DataFrameReader.load(DataFrameReader.scala:208)
	at org.apache.spark.sql.DataFrameReader.load(DataFrameReader.scala:172)
	at java.base/jdk.internal.reflect.NativeMethodAccessorImpl.invoke0(Native Method)
	at java.base/jdk.internal.reflect.NativeMethodAccessorImpl.invoke(NativeMethodAccessorImpl.java:62)
	at java.base/jdk.internal.reflect.DelegatingMethodAccessorImpl.invoke(DelegatingMethodAccessorImpl.java:43)
	at java.base/java.lang.reflect.Method.invoke(Method.java:566)
	at py4j.reflection.MethodInvoker.invoke(MethodInvoker.java:244)
	at py4j.reflection.ReflectionEngine.invoke(ReflectionEngine.java:374)
	at py4j.Gateway.invoke(Gateway.java:282)
	at py4j.commands.AbstractCommand.invokeMethod(AbstractCommand.java:132)
	at py4j.commands.CallCommand.execute(CallCommand.java:79)
	at py4j.ClientServerConnection.waitForCommands(ClientServerConnection.java:182)
	at py4j.ClientServerConnection.run(ClientServerConnection.java:106)
	at java.base/java.lang.Thread.run(Thread.java:829)
Caused by: java.lang.ClassNotFoundException: mongo.DefaultSource
	at java.base/java.net.URLClassLoader.findClass(URLClassLoader.java:476)
	at java.base/java.lang.ClassLoader.loadClass(ClassLoader.java:594)
	at java.base/java.lang.ClassLoader.loadClass(ClassLoader.java:527)
	at org.apache.spark.sql.execution.datasources.DataSource$.$anonfun$lookupDataSource$5(DataSource.scala:633)
	at scala.util.Try$.apply(Try.scala:213)
	at org.apache.spark.sql.execution.datasources.DataSource$.$anonfun$lookupDataSource$4(DataSource.scala:633)
	at scala.util.Failure.orElse(Try.scala:224)
	at org.apache.spark.sql.execution.datasources.DataSource$.lookupDataSource(DataSource.scala:633)
	... 15 more

[2023-09-30T10:23:01.558+0000] {taskinstance.py:1398} INFO - Marking task as UP_FOR_RETRY. dag_id=btc_market_analysis, task_id=load_data_from_mongo, execution_date=20230930T094805, start_date=20230930T102255, end_date=20230930T102301
[2023-09-30T10:23:01.583+0000] {standard_task_runner.py:104} ERROR - Failed to execute job 29 for task load_data_from_mongo (An error occurred while calling o29.load.
: org.apache.spark.SparkClassNotFoundException: [DATA_SOURCE_NOT_FOUND] Failed to find the data source: mongo. Please find packages at `https://spark.apache.org/third-party-projects.html`.
	at org.apache.spark.sql.errors.QueryExecutionErrors$.dataSourceNotFoundError(QueryExecutionErrors.scala:724)
	at org.apache.spark.sql.execution.datasources.DataSource$.lookupDataSource(DataSource.scala:647)
	at org.apache.spark.sql.execution.datasources.DataSource$.lookupDataSourceV2(DataSource.scala:697)
	at org.apache.spark.sql.DataFrameReader.load(DataFrameReader.scala:208)
	at org.apache.spark.sql.DataFrameReader.load(DataFrameReader.scala:172)
	at java.base/jdk.internal.reflect.NativeMethodAccessorImpl.invoke0(Native Method)
	at java.base/jdk.internal.reflect.NativeMethodAccessorImpl.invoke(NativeMethodAccessorImpl.java:62)
	at java.base/jdk.internal.reflect.DelegatingMethodAccessorImpl.invoke(DelegatingMethodAccessorImpl.java:43)
	at java.base/java.lang.reflect.Method.invoke(Method.java:566)
	at py4j.reflection.MethodInvoker.invoke(MethodInvoker.java:244)
	at py4j.reflection.ReflectionEngine.invoke(ReflectionEngine.java:374)
	at py4j.Gateway.invoke(Gateway.java:282)
	at py4j.commands.AbstractCommand.invokeMethod(AbstractCommand.java:132)
	at py4j.commands.CallCommand.execute(CallCommand.java:79)
	at py4j.ClientServerConnection.waitForCommands(ClientServerConnection.java:182)
	at py4j.ClientServerConnection.run(ClientServerConnection.java:106)
	at java.base/java.lang.Thread.run(Thread.java:829)
Caused by: java.lang.ClassNotFoundException: mongo.DefaultSource
	at java.base/java.net.URLClassLoader.findClass(URLClassLoader.java:476)
	at java.base/java.lang.ClassLoader.loadClass(ClassLoader.java:594)
	at java.base/java.lang.ClassLoader.loadClass(ClassLoader.java:527)
	at org.apache.spark.sql.execution.datasources.DataSource$.$anonfun$lookupDataSource$5(DataSource.scala:633)
	at scala.util.Try$.apply(Try.scala:213)
	at org.apache.spark.sql.execution.datasources.DataSource$.$anonfun$lookupDataSource$4(DataSource.scala:633)
	at scala.util.Failure.orElse(Try.scala:224)
	at org.apache.spark.sql.execution.datasources.DataSource$.lookupDataSource(DataSource.scala:633)
	... 15 more
; 211)
[2023-09-30T10:23:01.638+0000] {local_task_job_runner.py:228} INFO - Task exited with return code 1
[2023-09-30T10:23:01.700+0000] {taskinstance.py:2776} INFO - 0 downstream tasks scheduled from follow-on schedule check
